<?xml version="1.0" encoding="utf-8"?>
<mujoco model="rotating_disk">
    <compiler eulerseq="XYZ" fitaabb="true" angle="radian"  autolimits="true"/>  
    <option timestep="0.001" gravity="0 0 -9.81"/>  
    
    <default>
        <joint damping="0.1"/>
    </default>

    <asset> 
        <texture name="skybox" type="skybox" builtin="gradient" rgb1="0.2 0.3 0.4" rgb2="0 0 0" width="1000" height="1000" mark="random" random="0.001" markrgb="1 1 1"/>  
        <texture type="2d" name="groundplane" builtin="checker" mark="edge" rgb1="0.2 0.3 0.4" rgb2="0.1 0.2 0.3" markrgb="0.8 0.8 0.8" width="1000" height="1000"/>  
        <material name="groundplane" texture="groundplane" texuniform="true" texrepeat="5 5" reflectance="0.2"/> 
    </asset>  
    
    <worldbody>
        <geom name="floor" pos="0 0 -0.5" size="0 0 1" type="plane" material="groundplane"/>
        <light directional="true" diffuse=".8 .8 .8" specular=".2 .2 .2" pos="0 0 5" dir="0 0 -1"/>
        
        <body name="stand" pos="0 0 0.5">
            <geom name="pole" type="cylinder" size="0.05 0.5" rgba="0.8 0.8 0.8 1" pos="0 0 -0.5"/>
            
            <body name="disk" pos="0 0 0">
                <joint name="spin" type="hinge" axis="0 0 1" pos="0 0 0"/>
                <geom name="disk_geom" type="cylinder" size="0.3 0.05" rgba="0. 0.5 0.7 0.4"/>
                
                <site name="imu" pos="0.25 0 0"/>
                <geom name="imu_visual" type="box" size="0.02 0.02 0.02" pos="0.25 0 0" rgba="1 0 0 1"/>
            </body>
        </body>

        <light pos="0 0 3" dir="0 0 -1" diffuse="0.8 0.8 0.8"/>
    </worldbody>
   
    <actuator>
        <velocity name="motor" joint="spin" kv="100" gear="1" ctrlrange="-5 5"/>
    </actuator>
   
    <sensor>
        <gyro name="angular-velocity" site="imu" noise="0"/>
        <accelerometer name="linear-acceleration" site="imu" noise="0"/>
        <framequat name="orientation" objtype="site" objname="imu" noise="0"/>
    </sensor>
</mujoco>