<?xml version="1.0" encoding="utf-8"?>

<mujoco model="2_joints_arm">
  <compiler eulerseq="XYZ" fitaabb="true" angle="radian"  autolimits="true"/>  
  <option timestep="0.001" gravity="0 0 -9.81"/>  
  <asset> 
    <texture name="skybox" type="skybox" builtin="gradient" rgb1="0.2 0.3 0.4" rgb2="0 0 0" width="1000" height="1000" mark="random" random="0.001" markrgb="1 1 1"/>  
    <texture type="2d" name="groundplane" builtin="checker" mark="edge" rgb1="0.2 0.3 0.4" rgb2="0.1 0.2 0.3" markrgb="0.8 0.8 0.8" width="1000" height="1000"/>  
    <material name="groundplane" texture="groundplane" texuniform="true" texrepeat="5 5" reflectance="0.2"/> 
  </asset>  

  <worldbody>
    <geom name="floor" pos="0 0 -0.5" size="0 0 1" type="plane" material="groundplane"/>
    <light directional="true" diffuse=".8 .8 .8" specular=".2 .2 .2" pos="0 0 5" dir="0 0 -1"/>
    <body pos="0 0 0.7">
      <geom name="upper arm" type="capsule" size="0.045" fromto="0 0 0  0.5 0 0" rgba="0.55 0.57 0.6 1"/>
      <joint name="shoulder" type="hinge" damping="0.1"  axis="0 1 0"/>
      <geom name="shoulder" type="cylinder" pos="0 0 0" size=".08 .05" rgba="0.4 0.42 0.45 1" mass="0" euler="1.5708 0 0" />
      <body pos="0.5 0 0">
        <geom name="forearm" type="capsule" size="0.035" fromto="0 0 0  0.5 0 0" rgba="0.55 0.57 0.6 1"/>
        <joint name="elbow" type="hinge" damping="0.1"  axis="0 0 1"/>
        <geom name="elbow" type="cylinder" pos="0 0 0" size=".06 .05" rgba="0.4 0.42 0.45 1" mass="0" />
      </body>
    </body>
  </worldbody>
  <actuator>
    <position name="shoulder_actuator" joint="shoulder" ctrlrange="-1.5708 1.5708" kp="1000" kv="50"/>
    <position name="elbow_actuator" joint="elbow" ctrlrange="-2.618 0" kp="1000" kv="50"/>
  </actuator>
  <sensor> 
    <jointpos name="jointpos_shoulder" joint="shoulder" noise="0.01"/>  
    <jointpos name="jointpos_elbow" joint="elbow" noise="0.05"/>  
  </sensor> 
</mujoco>
